<?xml version="1.0" ?>
<sdf version="1.5">
  <model name="simple_one_legged_robot">
    <static>false</static>
    
    <link name="torso">
      <gravity>0</gravity>
      <collision name="collision">
        <pose>0 0 8.5 0 0 0</pose>
        <geometry>
          <box>
            <size>3 1 3</size>
          </box>
        </geometry>
        <surface>
          <friction>
            <ode>
              <mu>100</mu>
              <mu2>50</mu2>
            </ode>
          </friction>
        </surface>
      </collision>
      <visual name="visual">
        <pose>0 0 8.5 0 0 0</pose>
        <geometry>
          <box>
            <size>3 1 3</size>
          </box>
        </geometry>
        <material>
          <script>
            <uri>file://media/materials/scripts/gazebo.material</uri>
            <name>Gazebo/Orange</name>
          </script>
        </material>
      </visual>
    </link>

    <link name="tigh">
      <gravity>0</gravity>
      <collision name="collision">
        <pose>0 0 5.5 0 0 0</pose>
        <geometry>
          <box>
            <size>1 1 3</size>
          </box>
        </geometry>
        <surface>
          <friction>
            <ode>
              <mu>100</mu>
              <mu2>50</mu2>
            </ode>
          </friction>
        </surface>
      </collision>
      <visual name="visual">
        <pose>0 0 5.5 0 0 0</pose>
        <geometry>
          <box>
            <size>1 1 3</size>
          </box>
        </geometry>
        <material>
          <script>
            <uri>file://media/materials/scripts/gazebo.material</uri>
            <name>Gazebo/Grey</name>
          </script>
        </material>
      </visual>
    </link>

    <link name="calf">
      <gravity>0</gravity>
      <collision name="collision">
        <pose>0 0 2.5 0 0 0</pose>
        <geometry>
          <box>
            <size>1 1 3</size>
          </box>
        </geometry>
        <surface>
          <friction>
            <ode>
              <mu>100</mu>
              <mu2>50</mu2>
            </ode>
          </friction>
        </surface>
      </collision>
      <visual name="visual">
        <pose>0 0 2.5 0 0 0</pose>
        <geometry>
          <box>
            <size>1 1 3</size>
          </box>
        </geometry>
        <material>
          <script>
            <uri>file://media/materials/scripts/gazebo.material</uri>
            <name>Gazebo/Orange</name>
          </script>
        </material>
      </visual>
    </link>

    <link name="foot">
      <gravity>0</gravity>
      <collision name="collision">
        <pose>0.5 0 0.5 0 0 0</pose>
        <geometry>
          <box>
            <size>1 2 1</size>
          </box>
        </geometry>
        <surface>
          <friction>
            <ode>
              <mu>100</mu>
              <mu2>50</mu2>
            </ode>
          </friction>
        </surface>
      </collision>
      <visual name="visual">
        <pose>0 0.5 0.5 0 0 0</pose>
        <geometry>
          <box>
            <size>1 2 1</size>
          </box>
        </geometry>
        <material>
          <script>
            <uri>file://media/materials/scripts/gazebo.material</uri>
            <name>Gazebo/Grey</name>
          </script>
        </material>
      </visual>
    </link>

    <joint type="revolute" name="hip">
      <pose>0 0 1.5 0 0 0</pose>
      <child>tigh</child>
      <parent>torso</parent>
      <axis>
        <xyz>1 0 0</xyz>
      </axis>
    </joint>

    <joint type="revolute" name="knee">
      <pose>0 0 1.5 0 0 0</pose>
      <child>calf</child>
      <parent>tigh</parent>
      <axis>
        <xyz>1 0 0</xyz>
      </axis>
    </joint>

    <joint type="revolute" name="ankle">
      <pose>0 0 0.5 0 0 0</pose>
      <child>foot</child>
      <parent>calf</parent>
      <axis>
        <xyz>1 0 0</xyz>
      </axis>
    </joint>
  </model>
</sdf>